
C:\Users\felip>cd C:\Tinf\programacion\proyectos\desafios_django\semana 1\miweb

C:\Tinf\programacion\proyectos\desafios_django\semana 1\miweb>cd C:\Tinf\programacion\proyectos\desafios_django\semana 1\miweb\principal\templates

C:\Tinf\programacion\proyectos\desafios_django\semana 1\miweb\principal\templates>cd C:\Tinf\programacion\proyectos\desafios_django\semana 1\miweb

C:\Tinf\programacion\proyectos\desafios_django\semana 1\miweb>. code
"." no se reconoce como un comando interno o externo,
programa o archivo por lotes ejecutable.

C:\Tinf\programacion\proyectos\desafios_django\semana 1\miweb>code .

C:\Tinf\programacion\proyectos\desafios_django\semana 1\miweb>env\Scripts\activate

(env) C:\Tinf\programacion\proyectos\desafios_django\semana 1\miweb>python manage.py runserver
Watching for file changes with StatReloader
Performing system checks...

System check identified no issues (0 silenced).

You have 18 unapplied migration(s). Your project may not work properly until you apply the migrations for app(s): admin, auth, contenttypes, sessions.
Run 'python manage.py migrate' to apply them.
June 18, 2025 - 06:10:46
Django version 5.2.2, using settings 'miweb.settings'
Starting development server at http://127.0.0.1:8000/
Quit the server with CTRL-BREAK.

WARNING: This is a development server. Do not use it in a production setting. Use a production WSGI or ASGI server instead.
For more information on production servers see: https://docs.djangoproject.com/en/5.2/howto/deployment/
Not Found: /
[18/Jun/2025 06:11:01] "GET / HTTP/1.1" 404 2915
Not Found: /favicon.ico
[18/Jun/2025 06:11:01] "GET /favicon.ico HTTP/1.1" 404 2966
^C
(env) C:\Tinf\programacion\proyectos\desafios_django\semana 1\miweb>code.
"code." no se reconoce como un comando interno o externo,
programa o archivo por lotes ejecutable.

(env) C:\Tinf\programacion\proyectos\desafios_django\semana 1\miweb>. code
"." no se reconoce como un comando interno o externo,
programa o archivo por lotes ejecutable.

(env) C:\Tinf\programacion\proyectos\desafios_django\semana 1\miweb>code .

(env) C:\Tinf\programacion\proyectos\desafios_django\semana 1\miweb>python manage.py runserver
Watching for file changes with StatReloader
Performing system checks...

System check identified no issues (0 silenced).

You have 18 unapplied migration(s). Your project may not work properly until you apply the migrations for app(s): admin, auth, contenttypes, sessions.
Run 'python manage.py migrate' to apply them.
June 18, 2025 - 06:13:40
Django version 5.2.2, using settings 'miweb.settings'
Starting development server at http://127.0.0.1:8000/
Quit the server with CTRL-BREAK.

WARNING: This is a development server. Do not use it in a production setting. Use a production WSGI or ASGI server instead.
For more information on production servers see: https://docs.djangoproject.com/en/5.2/howto/deployment/
Not Found: /
[18/Jun/2025 06:13:44] "GET / HTTP/1.1" 404 2915
Not Found: /
[18/Jun/2025 06:13:46] "GET / HTTP/1.1" 404 2915
Not Found: /
[18/Jun/2025 06:13:48] "GET / HTTP/1.1" 404 2915
Not Found: /
[18/Jun/2025 06:13:48] "GET / HTTP/1.1" 404 2915
Not Found: /
[18/Jun/2025 06:13:49] "GET / HTTP/1.1" 404 2915
Not Found: /
[18/Jun/2025 06:13:49] "GET / HTTP/1.1" 404 2915
Not Found: /
[18/Jun/2025 06:13:49] "GET / HTTP/1.1" 404 2915
Not Found: /
[18/Jun/2025 06:13:49] "GET / HTTP/1.1" 404 2915
^C
(env) C:\Tinf\programacion\proyectos\desafios_django\semana 1\miweb>python manage.py runserver
Watching for file changes with StatReloader
Performing system checks...

Exception in thread django-main-thread:
Traceback (most recent call last):
  File "C:\Users\felip\AppData\Local\Programs\Python\Python313\Lib\threading.py", line 1041, in _bootstrap_inner
    self.run()
    ~~~~~~~~^^
  File "C:\Users\felip\AppData\Local\Programs\Python\Python313\Lib\threading.py", line 992, in run
    self._target(*self._args, **self._kwargs)
    ~~~~~~~~~~~~^^^^^^^^^^^^^^^^^^^^^^^^^^^^^
  File "C:\Tinf\programacion\proyectos\desafios_django\semana 1\miweb\env\Lib\site-packages\django\utils\autoreload.py", line 64, in wrapper
    fn(*args, **kwargs)
    ~~^^^^^^^^^^^^^^^^^
  File "C:\Tinf\programacion\proyectos\desafios_django\semana 1\miweb\env\Lib\site-packages\django\core\management\commands\runserver.py", line 134, in inner_run
    self.check(**check_kwargs)
    ~~~~~~~~~~^^^^^^^^^^^^^^^^
  File "C:\Tinf\programacion\proyectos\desafios_django\semana 1\miweb\env\Lib\site-packages\django\core\management\base.py", line 492, in check
    all_issues = checks.run_checks(
        app_configs=app_configs,
    ...<2 lines>...
        databases=databases,
    )
  File "C:\Tinf\programacion\proyectos\desafios_django\semana 1\miweb\env\Lib\site-packages\django\core\checks\registry.py", line 89, in run_checks
    new_errors = check(app_configs=app_configs, databases=databases)
  File "C:\Tinf\programacion\proyectos\desafios_django\semana 1\miweb\env\Lib\site-packages\django\core\checks\urls.py", line 16, in check_url_config
    return check_resolver(resolver)
  File "C:\Tinf\programacion\proyectos\desafios_django\semana 1\miweb\env\Lib\site-packages\django\core\checks\urls.py", line 26, in check_resolver
    return check_method()
  File "C:\Tinf\programacion\proyectos\desafios_django\semana 1\miweb\env\Lib\site-packages\django\urls\resolvers.py", line 531, in check
    for pattern in self.url_patterns:
                   ^^^^^^^^^^^^^^^^^
  File "C:\Tinf\programacion\proyectos\desafios_django\semana 1\miweb\env\Lib\site-packages\django\utils\functional.py", line 47, in __get__
    res = instance.__dict__[self.name] = self.func(instance)
                                         ~~~~~~~~~^^^^^^^^^^
  File "C:\Tinf\programacion\proyectos\desafios_django\semana 1\miweb\env\Lib\site-packages\django\urls\resolvers.py", line 718, in url_patterns
    patterns = getattr(self.urlconf_module, "urlpatterns", self.urlconf_module)
                       ^^^^^^^^^^^^^^^^^^^
  File "C:\Tinf\programacion\proyectos\desafios_django\semana 1\miweb\env\Lib\site-packages\django\utils\functional.py", line 47, in __get__
    res = instance.__dict__[self.name] = self.func(instance)
                                         ~~~~~~~~~^^^^^^^^^^
  File "C:\Tinf\programacion\proyectos\desafios_django\semana 1\miweb\env\Lib\site-packages\django\urls\resolvers.py", line 711, in urlconf_module
    return import_module(self.urlconf_name)
  File "C:\Users\felip\AppData\Local\Programs\Python\Python313\Lib\importlib\__init__.py", line 88, in import_module
    return _bootstrap._gcd_import(name[level:], package, level)
           ~~~~~~~~~~~~~~~~~~~~~~^^^^^^^^^^^^^^^^^^^^^^^^^^^^^^
  File "<frozen importlib._bootstrap>", line 1387, in _gcd_import
  File "<frozen importlib._bootstrap>", line 1360, in _find_and_load
  File "<frozen importlib._bootstrap>", line 1331, in _find_and_load_unlocked
  File "<frozen importlib._bootstrap>", line 935, in _load_unlocked
  File "<frozen importlib._bootstrap_external>", line 1026, in exec_module
  File "<frozen importlib._bootstrap>", line 488, in _call_with_frames_removed
  File "C:\Tinf\programacion\proyectos\desafios_django\semana 1\miweb\miweb\urls.py", line 22, in <module>
    path("", include ("principal.urls")),
             ~~~~~~~~^^^^^^^^^^^^^^^^^^
  File "C:\Tinf\programacion\proyectos\desafios_django\semana 1\miweb\env\Lib\site-packages\django\urls\conf.py", line 39, in include
    urlconf_module = import_module(urlconf_module)
  File "C:\Users\felip\AppData\Local\Programs\Python\Python313\Lib\importlib\__init__.py", line 88, in import_module
    return _bootstrap._gcd_import(name[level:], package, level)
           ~~~~~~~~~~~~~~~~~~~~~~^^^^^^^^^^^^^^^^^^^^^^^^^^^^^^
  File "<frozen importlib._bootstrap>", line 1387, in _gcd_import
  File "<frozen importlib._bootstrap>", line 1360, in _find_and_load
  File "<frozen importlib._bootstrap>", line 1331, in _find_and_load_unlocked
  File "<frozen importlib._bootstrap>", line 935, in _load_unlocked
  File "<frozen importlib._bootstrap_external>", line 1026, in exec_module
  File "<frozen importlib._bootstrap>", line 488, in _call_with_frames_removed
  File "C:\Tinf\programacion\proyectos\desafios_django\semana 1\miweb\principal\urls.py", line 9, in <module>
    path('inicio', views.inicio, name='inicio'),
                   ^^^^^^^^^^^^
AttributeError: module 'principal.views' has no attribute 'inicio'
C:\Tinf\programacion\proyectos\desafios_django\semana 1\miweb\principal\urls.py changed, reloading.
Watching for file changes with StatReloader
Performing system checks...

Exception in thread django-main-thread:
Traceback (most recent call last):
  File "C:\Users\felip\AppData\Local\Programs\Python\Python313\Lib\threading.py", line 1041, in _bootstrap_inner
    self.run()
    ~~~~~~~~^^
  File "C:\Users\felip\AppData\Local\Programs\Python\Python313\Lib\threading.py", line 992, in run
    self._target(*self._args, **self._kwargs)
    ~~~~~~~~~~~~^^^^^^^^^^^^^^^^^^^^^^^^^^^^^
  File "C:\Tinf\programacion\proyectos\desafios_django\semana 1\miweb\env\Lib\site-packages\django\utils\autoreload.py", line 64, in wrapper
    fn(*args, **kwargs)
    ~~^^^^^^^^^^^^^^^^^
  File "C:\Tinf\programacion\proyectos\desafios_django\semana 1\miweb\env\Lib\site-packages\django\core\management\commands\runserver.py", line 134, in inner_run
    self.check(**check_kwargs)
    ~~~~~~~~~~^^^^^^^^^^^^^^^^
  File "C:\Tinf\programacion\proyectos\desafios_django\semana 1\miweb\env\Lib\site-packages\django\core\management\base.py", line 492, in check
    all_issues = checks.run_checks(
        app_configs=app_configs,
    ...<2 lines>...
        databases=databases,
    )
  File "C:\Tinf\programacion\proyectos\desafios_django\semana 1\miweb\env\Lib\site-packages\django\core\checks\registry.py", line 89, in run_checks
    new_errors = check(app_configs=app_configs, databases=databases)
  File "C:\Tinf\programacion\proyectos\desafios_django\semana 1\miweb\env\Lib\site-packages\django\core\checks\urls.py", line 16, in check_url_config
    return check_resolver(resolver)
  File "C:\Tinf\programacion\proyectos\desafios_django\semana 1\miweb\env\Lib\site-packages\django\core\checks\urls.py", line 26, in check_resolver
    return check_method()
  File "C:\Tinf\programacion\proyectos\desafios_django\semana 1\miweb\env\Lib\site-packages\django\urls\resolvers.py", line 531, in check
    for pattern in self.url_patterns:
                   ^^^^^^^^^^^^^^^^^
  File "C:\Tinf\programacion\proyectos\desafios_django\semana 1\miweb\env\Lib\site-packages\django\utils\functional.py", line 47, in __get__
    res = instance.__dict__[self.name] = self.func(instance)
                                         ~~~~~~~~~^^^^^^^^^^
  File "C:\Tinf\programacion\proyectos\desafios_django\semana 1\miweb\env\Lib\site-packages\django\urls\resolvers.py", line 718, in url_patterns
    patterns = getattr(self.urlconf_module, "urlpatterns", self.urlconf_module)
                       ^^^^^^^^^^^^^^^^^^^
  File "C:\Tinf\programacion\proyectos\desafios_django\semana 1\miweb\env\Lib\site-packages\django\utils\functional.py", line 47, in __get__
    res = instance.__dict__[self.name] = self.func(instance)
                                         ~~~~~~~~~^^^^^^^^^^
  File "C:\Tinf\programacion\proyectos\desafios_django\semana 1\miweb\env\Lib\site-packages\django\urls\resolvers.py", line 711, in urlconf_module
    return import_module(self.urlconf_name)
  File "C:\Users\felip\AppData\Local\Programs\Python\Python313\Lib\importlib\__init__.py", line 88, in import_module
    return _bootstrap._gcd_import(name[level:], package, level)
           ~~~~~~~~~~~~~~~~~~~~~~^^^^^^^^^^^^^^^^^^^^^^^^^^^^^^
  File "<frozen importlib._bootstrap>", line 1387, in _gcd_import
  File "<frozen importlib._bootstrap>", line 1360, in _find_and_load
  File "<frozen importlib._bootstrap>", line 1331, in _find_and_load_unlocked
  File "<frozen importlib._bootstrap>", line 935, in _load_unlocked
  File "<frozen importlib._bootstrap_external>", line 1026, in exec_module
  File "<frozen importlib._bootstrap>", line 488, in _call_with_frames_removed
  File "C:\Tinf\programacion\proyectos\desafios_django\semana 1\miweb\miweb\urls.py", line 22, in <module>
    path("", include ("principal.urls")),
             ~~~~~~~~^^^^^^^^^^^^^^^^^^
  File "C:\Tinf\programacion\proyectos\desafios_django\semana 1\miweb\env\Lib\site-packages\django\urls\conf.py", line 39, in include
    urlconf_module = import_module(urlconf_module)
  File "C:\Users\felip\AppData\Local\Programs\Python\Python313\Lib\importlib\__init__.py", line 88, in import_module
    return _bootstrap._gcd_import(name[level:], package, level)
           ~~~~~~~~~~~~~~~~~~~~~~^^^^^^^^^^^^^^^^^^^^^^^^^^^^^^
  File "<frozen importlib._bootstrap>", line 1387, in _gcd_import
  File "<frozen importlib._bootstrap>", line 1360, in _find_and_load
  File "<frozen importlib._bootstrap>", line 1331, in _find_and_load_unlocked
  File "<frozen importlib._bootstrap>", line 935, in _load_unlocked
  File "<frozen importlib._bootstrap_external>", line 1026, in exec_module
  File "<frozen importlib._bootstrap>", line 488, in _call_with_frames_removed
  File "C:\Tinf\programacion\proyectos\desafios_django\semana 1\miweb\principal\urls.py", line 9, in <module>
    path('inicio', views.inicio,),
                   ^^^^^^^^^^^^
AttributeError: module 'principal.views' has no attribute 'inicio'
^C
(env) C:\Tinf\programacion\proyectos\desafios_django\semana 1\miweb>python manage.py runserver
Watching for file changes with StatReloader
Performing system checks...

Exception in thread django-main-thread:
Traceback (most recent call last):
  File "C:\Users\felip\AppData\Local\Programs\Python\Python313\Lib\threading.py", line 1041, in _bootstrap_inner
    self.run()
    ~~~~~~~~^^
  File "C:\Users\felip\AppData\Local\Programs\Python\Python313\Lib\threading.py", line 992, in run
    self._target(*self._args, **self._kwargs)
    ~~~~~~~~~~~~^^^^^^^^^^^^^^^^^^^^^^^^^^^^^
  File "C:\Tinf\programacion\proyectos\desafios_django\semana 1\miweb\env\Lib\site-packages\django\utils\autoreload.py", line 64, in wrapper
    fn(*args, **kwargs)
    ~~^^^^^^^^^^^^^^^^^
  File "C:\Tinf\programacion\proyectos\desafios_django\semana 1\miweb\env\Lib\site-packages\django\core\management\commands\runserver.py", line 134, in inner_run
    self.check(**check_kwargs)
    ~~~~~~~~~~^^^^^^^^^^^^^^^^
  File "C:\Tinf\programacion\proyectos\desafios_django\semana 1\miweb\env\Lib\site-packages\django\core\management\base.py", line 492, in check
    all_issues = checks.run_checks(
        app_configs=app_configs,
    ...<2 lines>...
        databases=databases,
    )
  File "C:\Tinf\programacion\proyectos\desafios_django\semana 1\miweb\env\Lib\site-packages\django\core\checks\registry.py", line 89, in run_checks
    new_errors = check(app_configs=app_configs, databases=databases)
  File "C:\Tinf\programacion\proyectos\desafios_django\semana 1\miweb\env\Lib\site-packages\django\core\checks\urls.py", line 16, in check_url_config
    return check_resolver(resolver)
  File "C:\Tinf\programacion\proyectos\desafios_django\semana 1\miweb\env\Lib\site-packages\django\core\checks\urls.py", line 26, in check_resolver
    return check_method()
  File "C:\Tinf\programacion\proyectos\desafios_django\semana 1\miweb\env\Lib\site-packages\django\urls\resolvers.py", line 531, in check
    for pattern in self.url_patterns:
                   ^^^^^^^^^^^^^^^^^
  File "C:\Tinf\programacion\proyectos\desafios_django\semana 1\miweb\env\Lib\site-packages\django\utils\functional.py", line 47, in __get__
    res = instance.__dict__[self.name] = self.func(instance)
                                         ~~~~~~~~~^^^^^^^^^^
  File "C:\Tinf\programacion\proyectos\desafios_django\semana 1\miweb\env\Lib\site-packages\django\urls\resolvers.py", line 718, in url_patterns
    patterns = getattr(self.urlconf_module, "urlpatterns", self.urlconf_module)
                       ^^^^^^^^^^^^^^^^^^^
  File "C:\Tinf\programacion\proyectos\desafios_django\semana 1\miweb\env\Lib\site-packages\django\utils\functional.py", line 47, in __get__
    res = instance.__dict__[self.name] = self.func(instance)
                                         ~~~~~~~~~^^^^^^^^^^
  File "C:\Tinf\programacion\proyectos\desafios_django\semana 1\miweb\env\Lib\site-packages\django\urls\resolvers.py", line 711, in urlconf_module
    return import_module(self.urlconf_name)
  File "C:\Users\felip\AppData\Local\Programs\Python\Python313\Lib\importlib\__init__.py", line 88, in import_module
    return _bootstrap._gcd_import(name[level:], package, level)
           ~~~~~~~~~~~~~~~~~~~~~~^^^^^^^^^^^^^^^^^^^^^^^^^^^^^^
  File "<frozen importlib._bootstrap>", line 1387, in _gcd_import
  File "<frozen importlib._bootstrap>", line 1360, in _find_and_load
  File "<frozen importlib._bootstrap>", line 1331, in _find_and_load_unlocked
  File "<frozen importlib._bootstrap>", line 935, in _load_unlocked
  File "<frozen importlib._bootstrap_external>", line 1026, in exec_module
  File "<frozen importlib._bootstrap>", line 488, in _call_with_frames_removed
  File "C:\Tinf\programacion\proyectos\desafios_django\semana 1\miweb\miweb\urls.py", line 22, in <module>
    path("", include ("principal.urls")),
             ~~~~~~~~^^^^^^^^^^^^^^^^^^
  File "C:\Tinf\programacion\proyectos\desafios_django\semana 1\miweb\env\Lib\site-packages\django\urls\conf.py", line 39, in include
    urlconf_module = import_module(urlconf_module)
  File "C:\Users\felip\AppData\Local\Programs\Python\Python313\Lib\importlib\__init__.py", line 88, in import_module
    return _bootstrap._gcd_import(name[level:], package, level)
           ~~~~~~~~~~~~~~~~~~~~~~^^^^^^^^^^^^^^^^^^^^^^^^^^^^^^
  File "<frozen importlib._bootstrap>", line 1387, in _gcd_import
  File "<frozen importlib._bootstrap>", line 1360, in _find_and_load
  File "<frozen importlib._bootstrap>", line 1331, in _find_and_load_unlocked
  File "<frozen importlib._bootstrap>", line 935, in _load_unlocked
  File "<frozen importlib._bootstrap_external>", line 1026, in exec_module
  File "<frozen importlib._bootstrap>", line 488, in _call_with_frames_removed
  File "C:\Tinf\programacion\proyectos\desafios_django\semana 1\miweb\principal\urls.py", line 9, in <module>
    path('inicio', views.inicio,),
                   ^^^^^^^^^^^^
AttributeError: module 'principal.views' has no attribute 'inicio'
^C
(env) C:\Tinf\programacion\proyectos\desafios_django\semana 1\miweb>python manage.py runserver
Watching for file changes with StatReloader
Performing system checks...

Exception in thread django-main-thread:
Traceback (most recent call last):
  File "C:\Users\felip\AppData\Local\Programs\Python\Python313\Lib\threading.py", line 1041, in _bootstrap_inner
    self.run()
    ~~~~~~~~^^
  File "C:\Users\felip\AppData\Local\Programs\Python\Python313\Lib\threading.py", line 992, in run
    self._target(*self._args, **self._kwargs)
    ~~~~~~~~~~~~^^^^^^^^^^^^^^^^^^^^^^^^^^^^^
  File "C:\Tinf\programacion\proyectos\desafios_django\semana 1\miweb\env\Lib\site-packages\django\utils\autoreload.py", line 64, in wrapper
    fn(*args, **kwargs)
    ~~^^^^^^^^^^^^^^^^^
  File "C:\Tinf\programacion\proyectos\desafios_django\semana 1\miweb\env\Lib\site-packages\django\core\management\commands\runserver.py", line 134, in inner_run
    self.check(**check_kwargs)
    ~~~~~~~~~~^^^^^^^^^^^^^^^^
  File "C:\Tinf\programacion\proyectos\desafios_django\semana 1\miweb\env\Lib\site-packages\django\core\management\base.py", line 492, in check
    all_issues = checks.run_checks(
        app_configs=app_configs,
    ...<2 lines>...
        databases=databases,
    )
  File "C:\Tinf\programacion\proyectos\desafios_django\semana 1\miweb\env\Lib\site-packages\django\core\checks\registry.py", line 89, in run_checks
    new_errors = check(app_configs=app_configs, databases=databases)
  File "C:\Tinf\programacion\proyectos\desafios_django\semana 1\miweb\env\Lib\site-packages\django\core\checks\urls.py", line 16, in check_url_config
    return check_resolver(resolver)
  File "C:\Tinf\programacion\proyectos\desafios_django\semana 1\miweb\env\Lib\site-packages\django\core\checks\urls.py", line 26, in check_resolver
    return check_method()
  File "C:\Tinf\programacion\proyectos\desafios_django\semana 1\miweb\env\Lib\site-packages\django\urls\resolvers.py", line 531, in check
    for pattern in self.url_patterns:
                   ^^^^^^^^^^^^^^^^^
  File "C:\Tinf\programacion\proyectos\desafios_django\semana 1\miweb\env\Lib\site-packages\django\utils\functional.py", line 47, in __get__
    res = instance.__dict__[self.name] = self.func(instance)
                                         ~~~~~~~~~^^^^^^^^^^
  File "C:\Tinf\programacion\proyectos\desafios_django\semana 1\miweb\env\Lib\site-packages\django\urls\resolvers.py", line 718, in url_patterns
    patterns = getattr(self.urlconf_module, "urlpatterns", self.urlconf_module)
                       ^^^^^^^^^^^^^^^^^^^
  File "C:\Tinf\programacion\proyectos\desafios_django\semana 1\miweb\env\Lib\site-packages\django\utils\functional.py", line 47, in __get__
    res = instance.__dict__[self.name] = self.func(instance)
                                         ~~~~~~~~~^^^^^^^^^^
  File "C:\Tinf\programacion\proyectos\desafios_django\semana 1\miweb\env\Lib\site-packages\django\urls\resolvers.py", line 711, in urlconf_module
    return import_module(self.urlconf_name)
  File "C:\Users\felip\AppData\Local\Programs\Python\Python313\Lib\importlib\__init__.py", line 88, in import_module
    return _bootstrap._gcd_import(name[level:], package, level)
           ~~~~~~~~~~~~~~~~~~~~~~^^^^^^^^^^^^^^^^^^^^^^^^^^^^^^
  File "<frozen importlib._bootstrap>", line 1387, in _gcd_import
  File "<frozen importlib._bootstrap>", line 1360, in _find_and_load
  File "<frozen importlib._bootstrap>", line 1331, in _find_and_load_unlocked
  File "<frozen importlib._bootstrap>", line 935, in _load_unlocked
  File "<frozen importlib._bootstrap_external>", line 1026, in exec_module
  File "<frozen importlib._bootstrap>", line 488, in _call_with_frames_removed
  File "C:\Tinf\programacion\proyectos\desafios_django\semana 1\miweb\miweb\urls.py", line 22, in <module>
    path("", include ("principal.urls")),
             ~~~~~~~~^^^^^^^^^^^^^^^^^^
  File "C:\Tinf\programacion\proyectos\desafios_django\semana 1\miweb\env\Lib\site-packages\django\urls\conf.py", line 39, in include
    urlconf_module = import_module(urlconf_module)
  File "C:\Users\felip\AppData\Local\Programs\Python\Python313\Lib\importlib\__init__.py", line 88, in import_module
    return _bootstrap._gcd_import(name[level:], package, level)
           ~~~~~~~~~~~~~~~~~~~~~~^^^^^^^^^^^^^^^^^^^^^^^^^^^^^^
  File "<frozen importlib._bootstrap>", line 1387, in _gcd_import
  File "<frozen importlib._bootstrap>", line 1360, in _find_and_load
  File "<frozen importlib._bootstrap>", line 1331, in _find_and_load_unlocked
  File "<frozen importlib._bootstrap>", line 935, in _load_unlocked
  File "<frozen importlib._bootstrap_external>", line 1026, in exec_module
  File "<frozen importlib._bootstrap>", line 488, in _call_with_frames_removed
  File "C:\Tinf\programacion\proyectos\desafios_django\semana 1\miweb\principal\urls.py", line 9, in <module>
    path('inicio', views.inicio, name='inicio'),
                   ^^^^^^^^^^^^
AttributeError: module 'principal.views' has no attribute 'inicio'
^C
(env) C:\Tinf\programacion\proyectos\desafios_django\semana 1\miweb>python manage.py runserver
Watching for file changes with StatReloader
Performing system checks...

Exception in thread django-main-thread:
Traceback (most recent call last):
  File "C:\Users\felip\AppData\Local\Programs\Python\Python313\Lib\threading.py", line 1041, in _bootstrap_inner
    self.run()
    ~~~~~~~~^^
  File "C:\Users\felip\AppData\Local\Programs\Python\Python313\Lib\threading.py", line 992, in run
    self._target(*self._args, **self._kwargs)
    ~~~~~~~~~~~~^^^^^^^^^^^^^^^^^^^^^^^^^^^^^
  File "C:\Tinf\programacion\proyectos\desafios_django\semana 1\miweb\env\Lib\site-packages\django\utils\autoreload.py", line 64, in wrapper
    fn(*args, **kwargs)
    ~~^^^^^^^^^^^^^^^^^
  File "C:\Tinf\programacion\proyectos\desafios_django\semana 1\miweb\env\Lib\site-packages\django\core\management\commands\runserver.py", line 134, in inner_run
    self.check(**check_kwargs)
    ~~~~~~~~~~^^^^^^^^^^^^^^^^
  File "C:\Tinf\programacion\proyectos\desafios_django\semana 1\miweb\env\Lib\site-packages\django\core\management\base.py", line 492, in check
    all_issues = checks.run_checks(
        app_configs=app_configs,
    ...<2 lines>...
        databases=databases,
    )
  File "C:\Tinf\programacion\proyectos\desafios_django\semana 1\miweb\env\Lib\site-packages\django\core\checks\registry.py", line 89, in run_checks
    new_errors = check(app_configs=app_configs, databases=databases)
  File "C:\Tinf\programacion\proyectos\desafios_django\semana 1\miweb\env\Lib\site-packages\django\core\checks\urls.py", line 16, in check_url_config
    return check_resolver(resolver)
  File "C:\Tinf\programacion\proyectos\desafios_django\semana 1\miweb\env\Lib\site-packages\django\core\checks\urls.py", line 26, in check_resolver
    return check_method()
  File "C:\Tinf\programacion\proyectos\desafios_django\semana 1\miweb\env\Lib\site-packages\django\urls\resolvers.py", line 531, in check
    for pattern in self.url_patterns:
                   ^^^^^^^^^^^^^^^^^
  File "C:\Tinf\programacion\proyectos\desafios_django\semana 1\miweb\env\Lib\site-packages\django\utils\functional.py", line 47, in __get__
    res = instance.__dict__[self.name] = self.func(instance)
                                         ~~~~~~~~~^^^^^^^^^^
  File "C:\Tinf\programacion\proyectos\desafios_django\semana 1\miweb\env\Lib\site-packages\django\urls\resolvers.py", line 718, in url_patterns
    patterns = getattr(self.urlconf_module, "urlpatterns", self.urlconf_module)
                       ^^^^^^^^^^^^^^^^^^^
  File "C:\Tinf\programacion\proyectos\desafios_django\semana 1\miweb\env\Lib\site-packages\django\utils\functional.py", line 47, in __get__
    res = instance.__dict__[self.name] = self.func(instance)
                                         ~~~~~~~~~^^^^^^^^^^
  File "C:\Tinf\programacion\proyectos\desafios_django\semana 1\miweb\env\Lib\site-packages\django\urls\resolvers.py", line 711, in urlconf_module
    return import_module(self.urlconf_name)
  File "C:\Users\felip\AppData\Local\Programs\Python\Python313\Lib\importlib\__init__.py", line 88, in import_module
    return _bootstrap._gcd_import(name[level:], package, level)
           ~~~~~~~~~~~~~~~~~~~~~~^^^^^^^^^^^^^^^^^^^^^^^^^^^^^^
  File "<frozen importlib._bootstrap>", line 1387, in _gcd_import
  File "<frozen importlib._bootstrap>", line 1360, in _find_and_load
  File "<frozen importlib._bootstrap>", line 1331, in _find_and_load_unlocked
  File "<frozen importlib._bootstrap>", line 935, in _load_unlocked
  File "<frozen importlib._bootstrap_external>", line 1026, in exec_module
  File "<frozen importlib._bootstrap>", line 488, in _call_with_frames_removed
  File "C:\Tinf\programacion\proyectos\desafios_django\semana 1\miweb\miweb\urls.py", line 22, in <module>
    path("", include ("principal.urls")),
             ~~~~~~~~^^^^^^^^^^^^^^^^^^
  File "C:\Tinf\programacion\proyectos\desafios_django\semana 1\miweb\env\Lib\site-packages\django\urls\conf.py", line 39, in include
    urlconf_module = import_module(urlconf_module)
  File "C:\Users\felip\AppData\Local\Programs\Python\Python313\Lib\importlib\__init__.py", line 88, in import_module
    return _bootstrap._gcd_import(name[level:], package, level)
           ~~~~~~~~~~~~~~~~~~~~~~^^^^^^^^^^^^^^^^^^^^^^^^^^^^^^
  File "<frozen importlib._bootstrap>", line 1387, in _gcd_import
  File "<frozen importlib._bootstrap>", line 1360, in _find_and_load
  File "<frozen importlib._bootstrap>", line 1331, in _find_and_load_unlocked
  File "<frozen importlib._bootstrap>", line 935, in _load_unlocked
  File "<frozen importlib._bootstrap_external>", line 1026, in exec_module
  File "<frozen importlib._bootstrap>", line 488, in _call_with_frames_removed
  File "C:\Tinf\programacion\proyectos\desafios_django\semana 1\miweb\principal\urls.py", line 9, in <module>
    path('', views.inicio, name='inicio'),
             ^^^^^^^^^^^^
AttributeError: module 'principal.views' has no attribute 'inicio'
^C
(env) C:\Tinf\programacion\proyectos\desafios_django\semana 1\miweb>python manage.py runserver
Watching for file changes with StatReloader
Performing system checks...

Exception in thread django-main-thread:
Traceback (most recent call last):
  File "C:\Users\felip\AppData\Local\Programs\Python\Python313\Lib\threading.py", line 1041, in _bootstrap_inner
    self.run()
    ~~~~~~~~^^
  File "C:\Users\felip\AppData\Local\Programs\Python\Python313\Lib\threading.py", line 992, in run
    self._target(*self._args, **self._kwargs)
    ~~~~~~~~~~~~^^^^^^^^^^^^^^^^^^^^^^^^^^^^^
  File "C:\Tinf\programacion\proyectos\desafios_django\semana 1\miweb\env\Lib\site-packages\django\utils\autoreload.py", line 64, in wrapper
    fn(*args, **kwargs)
    ~~^^^^^^^^^^^^^^^^^
  File "C:\Tinf\programacion\proyectos\desafios_django\semana 1\miweb\env\Lib\site-packages\django\core\management\commands\runserver.py", line 134, in inner_run
    self.check(**check_kwargs)
    ~~~~~~~~~~^^^^^^^^^^^^^^^^
  File "C:\Tinf\programacion\proyectos\desafios_django\semana 1\miweb\env\Lib\site-packages\django\core\management\base.py", line 492, in check
    all_issues = checks.run_checks(
        app_configs=app_configs,
    ...<2 lines>...
        databases=databases,
    )
  File "C:\Tinf\programacion\proyectos\desafios_django\semana 1\miweb\env\Lib\site-packages\django\core\checks\registry.py", line 89, in run_checks
    new_errors = check(app_configs=app_configs, databases=databases)
  File "C:\Tinf\programacion\proyectos\desafios_django\semana 1\miweb\env\Lib\site-packages\django\core\checks\urls.py", line 16, in check_url_config
    return check_resolver(resolver)
  File "C:\Tinf\programacion\proyectos\desafios_django\semana 1\miweb\env\Lib\site-packages\django\core\checks\urls.py", line 26, in check_resolver
    return check_method()
  File "C:\Tinf\programacion\proyectos\desafios_django\semana 1\miweb\env\Lib\site-packages\django\urls\resolvers.py", line 531, in check
    for pattern in self.url_patterns:
                   ^^^^^^^^^^^^^^^^^
  File "C:\Tinf\programacion\proyectos\desafios_django\semana 1\miweb\env\Lib\site-packages\django\utils\functional.py", line 47, in __get__
    res = instance.__dict__[self.name] = self.func(instance)
                                         ~~~~~~~~~^^^^^^^^^^
  File "C:\Tinf\programacion\proyectos\desafios_django\semana 1\miweb\env\Lib\site-packages\django\urls\resolvers.py", line 718, in url_patterns
    patterns = getattr(self.urlconf_module, "urlpatterns", self.urlconf_module)
                       ^^^^^^^^^^^^^^^^^^^
  File "C:\Tinf\programacion\proyectos\desafios_django\semana 1\miweb\env\Lib\site-packages\django\utils\functional.py", line 47, in __get__
    res = instance.__dict__[self.name] = self.func(instance)
                                         ~~~~~~~~~^^^^^^^^^^
  File "C:\Tinf\programacion\proyectos\desafios_django\semana 1\miweb\env\Lib\site-packages\django\urls\resolvers.py", line 711, in urlconf_module
    return import_module(self.urlconf_name)
  File "C:\Users\felip\AppData\Local\Programs\Python\Python313\Lib\importlib\__init__.py", line 88, in import_module
    return _bootstrap._gcd_import(name[level:], package, level)
           ~~~~~~~~~~~~~~~~~~~~~~^^^^^^^^^^^^^^^^^^^^^^^^^^^^^^
  File "<frozen importlib._bootstrap>", line 1387, in _gcd_import
  File "<frozen importlib._bootstrap>", line 1360, in _find_and_load
  File "<frozen importlib._bootstrap>", line 1331, in _find_and_load_unlocked
  File "<frozen importlib._bootstrap>", line 935, in _load_unlocked
  File "<frozen importlib._bootstrap_external>", line 1026, in exec_module
  File "<frozen importlib._bootstrap>", line 488, in _call_with_frames_removed
  File "C:\Tinf\programacion\proyectos\desafios_django\semana 1\miweb\miweb\urls.py", line 22, in <module>
    path("", include ("principal.urls")),
             ~~~~~~~~^^^^^^^^^^^^^^^^^^
  File "C:\Tinf\programacion\proyectos\desafios_django\semana 1\miweb\env\Lib\site-packages\django\urls\conf.py", line 39, in include
    urlconf_module = import_module(urlconf_module)
  File "C:\Users\felip\AppData\Local\Programs\Python\Python313\Lib\importlib\__init__.py", line 88, in import_module
    return _bootstrap._gcd_import(name[level:], package, level)
           ~~~~~~~~~~~~~~~~~~~~~~^^^^^^^^^^^^^^^^^^^^^^^^^^^^^^
  File "<frozen importlib._bootstrap>", line 1387, in _gcd_import
  File "<frozen importlib._bootstrap>", line 1360, in _find_and_load
  File "<frozen importlib._bootstrap>", line 1331, in _find_and_load_unlocked
  File "<frozen importlib._bootstrap>", line 935, in _load_unlocked
  File "<frozen importlib._bootstrap_external>", line 1026, in exec_module
  File "<frozen importlib._bootstrap>", line 488, in _call_with_frames_removed
  File "C:\Tinf\programacion\proyectos\desafios_django\semana 1\miweb\principal\urls.py", line 9, in <module>
    path('', views.inicio, name='inicio'),
             ^^^^^^^^^^^^
AttributeError: module 'principal.views' has no attribute 'inicio'
C:\Tinf\programacion\proyectos\desafios_django\semana 1\miweb\principal\views.py changed, reloading.
Watching for file changes with StatReloader
Performing system checks...

System check identified no issues (0 silenced).

You have 18 unapplied migration(s). Your project may not work properly until you apply the migrations for app(s): admin, auth, contenttypes, sessions.
Run 'python manage.py migrate' to apply them.
June 18, 2025 - 06:28:36
Django version 5.2.2, using settings 'miweb.settings'
Starting development server at http://127.0.0.1:8000/
Quit the server with CTRL-BREAK.

WARNING: This is a development server. Do not use it in a production setting. Use a production WSGI or ASGI server instead.
For more information on production servers see: https://docs.djangoproject.com/en/5.2/howto/deployment/
[18/Jun/2025 06:29:18] "GET / HTTP/1.1" 200 446
^C
(env) C:\Tinf\programacion\proyectos\desafios_django\semana 1\miweb>
